Workbook

Sheet dashboard
A1: Sales Ops KPI Dashboard
A2: Use this tab to explain the operational story in an interview.
A3: KPI | B3: Value | C3: Interpretation
A4: CRM Gross Sales | B4: =reconciliation_summary!B4 -> 472328.52 | C4: CRM order demand
A5: ERP Invoice Amount | B5: =reconciliation_summary!B5 -> 429804.52 | C5: Invoiced revenue
A6: Variance | B6: =reconciliation_summary!B6 -> -42524 | C6: Difference needing review
A7: Open Exceptions | B7: =reconciliation_summary!B9 -> 934 | C7: Backlog count
A8: Critical Exceptions | B8: =reconciliation_summary!B10 -> 116 | C8: Highest-risk items
A9: Inventory Short Orders | B9: =reconciliation_summary!B11 -> 24 | C9: Fulfillment risk
A10: Orphan ERP Invoices | B10: =reconciliation_summary!B14 -> 5 | C10: ERP/data integrity risk
A13: Enterprise Realism Add-ons
A14: OTIF % | B14: =sla_metrics!B5 -> 0.21755725 | C14: Shipment performance
A15: Open Compliance Holds | B15: =sla_metrics!B8 -> 238 | C15: Regulatory / fulfillment blockers
A16: Credit Hold Recommendations | B16: =sla_metrics!B9 -> 93 | C16: AR risk
A17: Support SLA Breaches | B17: =sla_metrics!B7 -> 268 | C17: Customer support backlog
A18: Orphan ERP Invoices | B18: =reconciliation_summary!B14 -> 5 | C18: ERP/data integrity risk

Sheet executive_summary
A1: Executive Summary
A2: Plain-English narrative layer for an interview or portfolio walkthrough.
A3: Section | B3: Narrative
A4: Revenue readiness | B4: CRM demand, ERP invoices, credit memos, and AR aging should be reviewed together before publishing revenue-facing reporting. The workbook intentionally includes partial invoices, orphan invoices, credits, and timing gaps.
A5: Fulfillment risk | B5: Warehouse shipments now allow OTIF, short-ship, and hours-to-ship analysis. Use these to explain whether missed sales are demand issues or execution constraints.
A6: Compliance risk | B6: State-specific compliance review flags expired licenses, missing manifests, and restricted SKUs. This is especially relevant in regulated CPG/cannabis-style operations.
A7: Customer impact | B7: Support cases connect operational failures to customer-facing issues like invoice mismatches, late shipments, and damaged/refused deliveries.
A8: Cash impact | B8: Accounts receivable aging highlights invoices that are not just operationally complete but financially unresolved. Credit-hold recommendations help connect Sales Ops to Finance.
A9: Recommended next action | B9: Prioritize Critical compliance holds, orphan invoices, SLA-breached support cases, and AR balances in 61-90 or 90+ aging buckets before treating the period as clean.

Sheet crm_orders
A1: order_id | B1: order_date | C1: customer_id | D1: customer_name | E1: state | F1: sales_rep | G1: channel | H1: sku | I1: product_name | J1: qty_ordered | K1: unit_price | L1: gross_sales | M1: crm_status | N1: requested_ship_date | O1: available_inventory | P1: inventory_flag | Q1: duplicate_order_flag | R1: missing_key_flag | S1: order_value_band
A2: ORD000372 | B2: 46038 | D2: =IFERROR(VLOOKUP(C2,customer_lookup!$A:$E,2,FALSE),"") | E2: =IFERROR(VLOOKUP(C2,customer_lookup!$A:$E,3,FALSE),"") | F2: =IFERROR(VLOOKUP(C2,customer_lookup!$A:$E,5,FALSE),"") | G2: Wholesale | H2: SKU0019 | I2: =IFERROR(VLOOKUP(H2,product_lookup!$A:$D,2,FALSE),"") -> Cranberry Sparkling Beverage | J2: 60 | K2: 7.68 | L2: =J2*K2 -> 460.8 | M2: Fulfilled | N2: 46046 | O2: =SUMIF(inventory_snapshot!$B:$B,H2,inventory_snapshot!$E:$E) -> 1152 | P2: =IF(O2<J2,"Short","OK") -> OK | Q2: =IF(COUNTIF($A:$A,A2)>1,"Duplicate","OK") -> OK | R2: =IF(OR(C2="",H2=""),"Missing Key","OK") -> Missing Key | S2: =IF(L2>=1000,"Large",IF(L2>=500,"Medium","Small")) -> Small
A3: ORD000730 | B3: 46100 | D3: =IFERROR(VLOOKUP(C3,customer_lookup!$A:$E,2,FALSE),"") | E3: =IFERROR(VLOOKUP(C3,customer_lookup!$A:$E,3,FALSE),"") | F3: =IFERROR(VLOOKUP(C3,customer_lookup!$A:$E,5,FALSE),"") | G3: Retail | H3: SKU0012 | I3: =IFERROR(VLOOKUP(H3,product_lookup!$A:$D,2,FALSE),"") -> Sour Apple THC Gummies | J3: 120 | K3: 11.48 | L3: =J3*K3 -> 1377.6 | M3: Fulfilled | N3: 46101 | O3: =SUMIF(inventory_snapshot!$B:$B,H3,inventory_snapshot!$E:$E) -> 775 | P3: =IF(O3<J3,"Short","OK") -> OK | Q3: =IF(COUNTIF($A:$A,A3)>1,"Duplicate","OK") -> OK | R3: =IF(OR(C3="",H3=""),"Missing Key","OK") -> Missing Key | S3: =IF(L3>=1000,"Large",IF(L3>=500,"Medium","Small")) -> Large
A4: ORD000028 | B4: 46124 | C4: DSP0078 | D4: =IFERROR(VLOOKUP(C4,customer_lookup!$A:$E,2,FALSE),"") -> NV Account 0078 | E4: =IFERROR(VLOOKUP(C4,customer_lookup!$A:$E,3,FALSE),"") -> NV | F4: =IFERROR(VLOOKUP(C4,customer_lookup!$A:$E,5,FALSE),"") -> Alex | G4: Wholesale | H4: SKU0020 | I4: =IFERROR(VLOOKUP(H4,product_lookup!$A:$D,2,FALSE),"") -> Pineapple Sparkling Beverage | J4: 96 | K4: 7.32 | L4: =J4*K4 -> 702.72 | M4: Fulfilled | N4: 46132 | O4: =SUMIF(inventory_snapshot!$B:$B,H4,inventory_snapshot!$E:$E) -> 1145 | P4: =IF(O4<J4,"Short","OK") -> OK | Q4: =IF(COUNTIF($A:$A,A4)>1,"Duplicate","OK") -> OK | R4: =IF(OR(C4="",H4=""),"Missing Key","OK") -> OK | S4: =IF(L4>=1000,"Large",IF(L4>=500,"Medium","Small")) -> Medium
A5: ORD000034 | B5: 46033 | C5: DSP0064 | D5: =IFERROR(VLOOKUP(C5,customer_lookup!$A:$E,2,FALSE),"") -> CO Account 0064 | E5: =IFERROR(VLOOKUP(C5,customer_lookup!$A:$E,3,FALSE),"") -> CO | F5: =IFERROR(VLOOKUP(C5,customer_lookup!$A:$E,5,FALSE),"") -> Alex | G5: Wholesale | H5: SKU0015 | I5: =IFERROR(VLOOKUP(H5,product_lookup!$A:$D,2,FALSE),"") -> Strawberry 20:1 Gummies | J5: 96 | K5: 10.44 | L5: =J5*K5 -> 1002.24 | M5: Pending | N5: 46038 | O5: =SUMIF(inventory_snapshot!$B:$B,H5,inventory_snapshot!$E:$E) -> 2294 | P5: =IF(O5<J5,"Short","OK") -> OK | Q5: =IF(COUNTIF($A:$A,A5)>1,"Duplicate","OK") -> OK | R5: =IF(OR(C5="",H5=""),"Missing Key","OK") -> OK | S5: =IF(L5>=1000,"Large",IF(L5>=500,"Medium","Small")) -> Large
A6: ORD000042 | B6: 46105 | C6: DSP0060 | D6: =IFERROR(VLOOKUP(C6,customer_lookup!$A:$E,2,FALSE),"") -> OK Account 0060 | E6: =IFERROR(VLOOKUP(C6,customer_lookup!$A:$E,3,FALSE),"") -> OK | F6: =IFERROR(VLOOKUP(C6,customer_lookup!$A:$E,5,FALSE),"") -> Alex | G6: Wholesale | H6: SKU0004 | I6: =IFERROR(VLOOKUP(H6,product_lookup!$A:$D,2,FALSE),"") -> Grapefruit 1:1:1 Gummies | J6: 18 | K6: 10.75 | L6: =J6*K6 -> 193.5 | M6: Fulfilled | N6: 46110 | O6: =SUMIF(inventory_snapshot!$B:$B,H6,inventory_snapshot!$E:$E) -> 1751 | P6: =IF(O6<J6,"Short","OK") -> OK | Q6: =IF(COUNTIF($A:$A,A6)>1,"Duplicate","OK") -> OK | R6: =IF(OR(C6="",H6=""),"Missing Key","OK") -> OK | S6: =IF(L6>=1000,"Large",IF(L6>=500,"Medium","Small")) -> Small
A7: ORD000076 | B7: 46114 | C7: DSP0075 | D7: =IFERROR(VLOOKUP(C7,customer_lookup!$A:$E,2,FALSE),"") -> CA Account 0075 | E7: =IFERROR(VLOOKUP(C7,customer_lookup!$A:$E,3,FALSE),"") -> CA | F7: =IFERROR(VLOOKUP(C7,customer_lookup!$A:$E,5,FALSE),"") -> Alex | G7: Wholesale | H7: SKU0018 | I7: =IFERROR(VLOOKUP(H7,product_lookup!$A:$D,2,FALSE),"") -> Lemon Sparkling Beverage | J7: 36 | K7: 7.08 | L7: =J7*K7 -> 254.88 | M7: Fulfilled | N7: 46123 | O7: =SUMIF(inventory_snapshot!$B:$B,H7,inventory_snapshot!$E:$E) -> 1360 | P7: =IF(O7<J7,"Short","OK") -> OK | Q7: =IF(COUNTIF($A:$A,A7)>1,"Duplicate","OK") -> OK | R7: =IF(OR(C7="",H7=""),"Missing Key","OK") -> OK | S7: =IF(L7>=1000,"Large",IF(L7>=500,"Medium","Small")) -> Small
A8: ORD000087 | B8: 46079 | C8: DSP0063 | D8: =IFERROR(VLOOKUP(C8,customer_lookup!$A:$E,2,FALSE),"") -> CA Account 0063 | E8: =IFERROR(VLOOKUP(C8,customer_lookup!$A:$E,3,FALSE),"") -> CA | F8: =IFERROR(VLOOKUP(C8,customer_lookup!$A:$E,5,FALSE),"") -> Alex | G8: Wholesale | H8: SKU0020 | I8: =IFERROR(VLOOKUP(H8,product_lookup!$A:$D,2,FALSE),"") -> Pineapple Sparkling Beverage | J8: 48 | K8: 7.4 | L8: =J8*K8 -> 355.2 | M8: Fulfilled | N8: 46086 | O8: =SUMIF(inventory_snapshot!$B:$B,H8,inventory_snapshot!$E:$E) -> 1145 | P8: =IF(O8<J8,"Short","OK") -> OK | Q8: =IF(COUNTIF($A:$A,A8)>1,"Duplicate","OK") -> OK | R8: =IF(OR(C8="",H8=""),"Missing Key","OK") -> OK | S8: =IF(L8>=1000,"Large",IF(L8>=500,"Medium","Small")) -> Small
A9: ORD000103 | B9: 46140 | C9: DSP0075 | D9: =IFERROR(VLOOKUP(C9,customer_lookup!$A:$E,2,FALSE),"") -> CA Account 0075 | E9: =IFERROR(VLOOKUP(C9,customer_lookup!$A:$E,3,FALSE),"") -> CA | F9: =IFERROR(VLOOKUP(C9,customer_lookup!$A:$E,5,FALSE),"") -> Alex | G9: Retail | H9: SKU0005 | I9: =IFERROR(VLOOKUP(H9,product_lookup!$A:$D,2,FALSE),"") -> Huckleberry THC Gummies | J9: 36 | K9: 9.86 | L9: =J9*K9 -> 354.96 | M9: Fulfilled | N9: 46143 | O9: =SUMIF(inventory_snapshot!$B:$B,H9,inventory_snapshot!$E:$E) -> 1841 | P9: =IF(O9<J9,"Short","OK") -> OK | Q9: =IF(COUNTIF($A:$A,A9)>1,"Duplicate","OK") -> OK | R9: =IF(OR(C9="",H9=""),"Missing Key","OK") -> OK | S9: =IF(L9>=1000,"Large",IF(L9>=500,"Medium","Small")) -> Small
A10: ORD000104 | B10: 46071 | C10: DSP0040 | D10: =IFERROR(VLOOKUP(C10,customer_lookup!$A:$E,2,FALSE),"") -> CO Account 0040 | E10: =IFERROR(VLOOKUP(C10,customer_lookup!$A:$E,3,FALSE),"") -> CO | F10: =IFERROR(VLOOKUP(C10,customer_lookup!$A:$E,5,FALSE),"") -> Alex | G10: Retail | H10: SKU0018 | I10: =IFERROR(VLOOKUP(H10,product_lookup!$A:$D,2,FALSE),"") -> Lemon Sparkling Beverage | J10: 120 | K10: 7.67 | L10: =J10*K10 -> 920.4 | M10: Fulfilled | N10: 46080 | O10: =SUMIF(inventory_snapshot!$B:$B,H10,inventory_snapshot!$E:$E) -> 1360 | P10: =IF(O10<J10,"Short","OK") -> OK | Q10: =IF(COUNTIF($A:$A,A10)>1,"Duplicate","OK") -> OK | R10: =IF(OR(C10="",H10=""),"Missing Key","OK") -> OK | S10: =IF(L10>=1000,"Large",IF(L10>=500,"Medium","Small")) -> Medium
A11: ORD000156 | B11: 46044 | C11: DSP0075 | D11: =IFERROR(VLOOKUP(C11,customer_lookup!$A:$E,2,FALSE),"") -> CA Account 0075 | E11: =IFERROR(VLOOKUP(C11,customer_lookup!$A:$E,3,FALSE),"") -> CA | F11: =IFERROR(VLOOKUP(C11,customer_lookup!$A:$E,5,FALSE),"") -> Alex | G11: Distributor | H11: SKU0016 | I11: =IFERROR(VLOOKUP(H11,product_lookup!$A:$D,2,FALSE),"") -> Blackberry Sparkling Beverage | J11: 72 | K11: 7.69 | L11: =J11*K11 -> 553.68 | M11: Fulfilled | N11: 46047 | O11: =SUMIF(inventory_snapshot!$B:$B,H11,inventory_snapshot!$E:$E) -> 1292 | P11: =IF(O11<J11,"Short","OK") -> OK | Q11: =IF(COUNTIF($A:$A,A11)>1,"Duplicate","OK") -> OK | R11: =IF(OR(C11="",H11=""),"Missing Key","OK") -> OK | S11: =IF(L11>=1000,"Large",IF(L11>=500,"Medium","Small")) -> Medium
A12: ORD000161 | B12: 46084 | C12: DSP0063 | D12: =IFERROR(VLOOKUP(C12,customer_lookup!$A:$E,2,FALSE),"") -> CA Account 0063 | E12: =IFERROR(VLOOKUP(C12,customer_lookup!$A:$E,3,FALSE),"") -> CA | F12: =IFERROR(VLOOKUP(C12,customer_lookup!$A:$E,5,FALSE),"") -> Alex | G12: Retail | H12: SKU0011 | I12: =IFERROR(VLOOKUP(H12,product_lookup!$A:$D,2,FALSE),"") -> Raspberry THC Gummies | J12: 36 | K12: 10.63 | L12: =J12*K12 -> 382.68 | M12: Partial | N12: 46089 | O12: =SUMIF(inventory_snapshot!$B:$B,H12,inventory_snapshot!$E:$E) -> 1417 | P12: =IF(O12<J12,"Short","OK") -> OK | Q12: =IF(COUNTIF($A:$A,A12)>1,"Duplicate","OK") -> OK | R12: =IF(OR(C12="",H12=""),"Missing Key","OK") -> OK | S12: =IF(L12>=1000,"Large",IF(L12>=500,"Medium","Small")) -> Small
A13: ORD000189 | B13: 46067 | C13: DSP0064 | D13: =IFERROR(VLOOKUP(C13,customer_lookup!$A:$E,2,FALSE),"") -> CO Account 0064 | E13: =IFERROR(VLOOKUP(C13,customer_lookup!$A:$E,3,FALSE),"") -> CO | F13: =IFERROR(VLOOKUP(C13,customer_lookup!$A:$E,5,FALSE),"") -> Alex | G13: Wholesale | H13: SKU0002 | I13: =IFERROR(VLOOKUP(H13,product_lookup!$A:$D,2,FALSE),"") -> Boysenberry 1:1:1 Gummies | J13: 120 | K13: 10.86 | L13: =J13*K13 -> 1303.2 | M13: Fulfilled | N13: 46074 | O13: =SUMIF(inventory_snapshot!$B:$B,H13,inventory_snapshot!$E:$E) -> 2007 | P13: =IF(O13<J13,"Short","OK") -> OK | Q13: =IF(COUNTIF($A:$A,A13)>1,"Duplicate","OK") -> OK | R13: =IF(OR(C13="",H13=""),"Missing Key","OK") -> OK | S13: =IF(L13>=1000,"Large",IF(L13>=500,"Medium","Small")) -> Large
A14: ORD000196 | B14: 46125 | C14: DSP0060 | D14: =IFERROR(VLOOKUP(C14,customer_lookup!$A:$E,2,FALSE),"") -> OK Account 0060 | E14: =IFERROR(VLOOKUP(C14,customer_lookup!$A:$E,3,FALSE),"") -> OK | F14: =IFERROR(VLOOKUP(C14,customer_lookup!$A:$E,5,FALSE),"") -> Alex | G14: Wholesale | H14: SKU0004 | I14: =IFERROR(VLOOKUP(H14,product_lookup!$A:$D,2,FALSE),"") -> Grapefruit 1:1:1 Gummies | J14: 60 | K14: 11.31 | L14: =J14*K14 -> 678.6 | M14: Approved | N14: 46131 | O14: =SUMIF(inventory_snapshot!$B:$B,H14,inventory_snapshot!$E:$E) -> 1751 | P14: =IF(O14<J14,"Short","OK") -> OK | Q14: =IF(COUNTIF($A:$A,A14)>1,"Duplicate","OK") -> OK | R14: =IF(OR(C14="",H14=""),"Missing Key","OK") -> OK | S14: =IF(L14>=1000,"Large",IF(L14>=500,"Medium","Small")) -> Medium
A15: ORD000211 | B15: 46099 | C15: DSP0078 | D15: =IFERROR(VLOOKUP(C15,customer_lookup!$A:$E,2,FALSE),"") -> NV Account 0078 | E15: =IFERROR(VLOOKUP(C15,customer_lookup!$A:$E,3,FALSE),"") -> NV | F15: =IFERROR(VLOOKUP(C15,customer_lookup!$A:$E,5,FALSE),"") -> Alex | G15: Wholesale | H15: SKU0020 | I15: =IFERROR(VLOOKUP(H15,product_lookup!$A:$D,2,FALSE),"") -> Pineapple Sparkling Beverage | J15: 48 | K15: 8.48 | L15: =J15*K15 -> 407.04 | M15: Approved | N15: 46107 | O15: =SUMIF(inventory_snapshot!$B:$B,H15,inventory_snapshot!$E:$E) -> 1145 | P15: =IF(O15<J15,"Short","OK") -> OK | Q15: =IF(COUNTIF($A:$A,A15)>1,"Duplicate","OK") -> OK | R15: =IF(OR(C15="",H15=""),"Missing Key","OK") -> OK | S15: =IF(L15>=1000,"Large",IF(L15>=500,"Medium","Small")) -> Small
... A172: ORD000935 | B172: 46051 | C172: DSP0117 | D172: =IFERROR(VLOOKUP(C172,customer_lookup!$A:$E,2,FALSE),"") -> MO Account 0117 | E172: =IFERROR(VLOOKUP(C172,customer_lookup!$A:$E,3,FALSE),"") -> MO | F172: =IFERROR(VLOOKUP(C172,customer_lookup!$A:$E,5,FALSE),"") -> Avery | G172: Wholesale | H172: SKU0017 | I172: =IFERROR(VLOOKUP(H172,product_lookup!$A:$D,2,FALSE),"") -> Mango Sparkling Beverage | J172: 6 | K172: 7.63 | L172: =J172*K172 -> 45.78 | M172: Partial | N172: 46053 | O172: =SUMIF(inventory_snapshot!$B:$B,H172,inventory_snapshot!$E:$E) -> 1502 | P172: =IF(O172<J172,"Short","OK") -> OK | Q172: =IF(COUNTIF($A:$A,A172)>1,"Duplicate","OK") -> OK | R172: =IF(OR(C172="",H172=""),"Missing Key","OK") -> OK | S172: =IF(L172>=1000,"Large",IF(L172>=500,"Medium","Small")) -> Small
A173: ORD000938 | B173: 46119 | C173: DSP0084 | D173: =IFERROR(VLOOKUP(C173,customer_lookup!$A:$E,2,FALSE),"") -> OK Account 0084 | E173: =IFERROR(VLOOKUP(C173,customer_lookup!$A:$E,3,FALSE),"") -> OK | F173: =IFERROR(VLOOKUP(C173,customer_lookup!$A:$E,5,FALSE),"") -> Avery | G173: Wholesale | I173: =IFERROR(VLOOKUP(H173,product_lookup!$A:$D,2,FALSE),"") | J173: 24 | K173: 11.75 | L173: =J173*K173 -> 282 | M173: Partial | N173: 46129 | O173: =SUMIF(inventory_snapshot!$B:$B,H173,inventory_snapshot!$E:$E) -> 0 | P173: =IF(O173<J173,"Short","OK") -> Short | Q173: =IF(COUNTIF($A:$A,A173)>1,"Duplicate","OK") -> OK | R173: =IF(OR(C173="",H173=""),"Missing Key","OK") -> Missing Key | S173: =IF(L173>=1000,"Large",IF(L173>=500,"Medium","Small")) -> Small
A174: ORD000940 | B174: 46087 | C174: DSP0011 | D174: =IFERROR(VLOOKUP(C174,customer_lookup!$A:$E,2,FALSE),"") -> NY Account 0011 | E174: =IFERROR(VLOOKUP(C174,customer_lookup!$A:$E,3,FALSE),"") -> NY | F174: =IFERROR(VLOOKUP(C174,customer_lookup!$A:$E,5,FALSE),"") -> Avery | G174: Wholesale | H174: SKU0004 | I174: =IFERROR(VLOOKUP(H174,product_lookup!$A:$D,2,FALSE),"") -> Grapefruit 1:1:1 Gummies | J174: 30 | K174: 10.46 | L174: =J174*K174 -> 313.8 | M174: Fulfilled | N174: 46088 | O174: =SUMIF(inventory_snapshot!$B:$B,H174,inventory_snapshot!$E:$E) -> 1751 | P174: =IF(O174<J174,"Short","OK") -> OK | Q174: =IF(COUNTIF($A:$A,A174)>1,"Duplicate","OK") -> OK | R174: =IF(OR(C174="",H174=""),"Missing Key","OK") -> OK | S174: =IF(L174>=1000,"Large",IF(L174>=500,"Medium","Small")) -> Small
A175: ORD000967 | B175: 46029 | C175: DSP0099 | D175: =IFERROR(VLOOKUP(C175,customer_lookup!$A:$E,2,FALSE),"") -> CA Account 0099 | E175: =IFERROR(VLOOKUP(C175,customer_lookup!$A:$E,3,FALSE),"") -> CA | F175: =IFERROR(VLOOKUP(C175,customer_lookup!$A:$E,5,FALSE),"") -> Avery | G175: Wholesale | H175: SKU0008 | I175: =IFERROR(VLOOKUP(H175,product_lookup!$A:$D,2,FALSE),"") -> Peach 2:1 Gummies | J175: 36 | K175: 10.6 | L175: =J175*K175 -> 381.6 | M175: Fulfilled | N175: 46037 | O175: =SUMIF(inventory_snapshot!$B:$B,H175,inventory_snapshot!$E:$E) -> 1732 | P175: =IF(O175<J175,"Short","OK") -> OK | Q175: =IF(COUNTIF($A:$A,A175)>1,"Duplicate","OK") -> OK | R175: =IF(OR(C175="",H175=""),"Missing Key","OK") -> OK | S175: =IF(L175>=1000,"Large",IF(L175>=500,"Medium","Small")) -> Small
A176: ORD000973 | B176: 46035 | C176: DSP0117 | D176: =IFERROR(VLOOKUP(C176,customer_lookup!$A:$E,2,FALSE),"") -> MO Account 0117 | E176: =IFERROR(VLOOKUP(C176,customer_lookup!$A:$E,3,FALSE),"") -> MO | F176: =IFERROR(VLOOKUP(C176,customer_lookup!$A:$E,5,FALSE),"") -> Avery | G176: Wholesale | H176: SKU0020 | I176: =IFERROR(VLOOKUP(H176,product_lookup!$A:$D,2,FALSE),"") -> Pineapple Sparkling Beverage | J176: 30 | K176: 8.44 | L176: =J176*K176 -> 253.2 | M176: Approved | N176: 46037 | O176: =SUMIF(inventory_snapshot!$B:$B,H176,inventory_snapshot!$E:$E) -> 1145 | P176: =IF(O176<J176,"Short","OK") -> OK | Q176: =IF(COUNTIF($A:$A,A176)>1,"Duplicate","OK") -> OK | R176: =IF(OR(C176="",H176=""),"Missing Key","OK") -> OK | S176: =IF(L176>=1000,"Large",IF(L176>=500,"Medium","Small")) -> Small
A177: ORD000974 | B177: 46065 | C177: DSP0099 | D177: =IFERROR(VLOOKUP(C177,customer_lookup!$A:$E,2,FALSE),"") -> CA Account 0099 | E177: =IFERROR(VLOOKUP(C177,customer_lookup!$A:$E,3,FALSE),"") -> CA | F177: =IFERROR(VLOOKUP(C177,customer_lookup!$A:$E,5,FALSE),"") -> Avery | G177: Wholesale | H177: SKU0005 | I177: =IFERROR(VLOOKUP(H177,product_lookup!$A:$D,2,FALSE),"") -> Huckleberry THC Gummies | J177: 36 | K177: 10.75 | L177: =J177*K177 -> 387 | M177: Fulfilled | N177: 46069 | O177: =SUMIF(inventory_snapshot!$B:$B,H177,inventory_snapshot!$E:$E) -> 1841 | P177: =IF(O177<J177,"Short","OK") -> OK | Q177: =IF(COUNTIF($A:$A,A177)>1,"Duplicate","OK") -> OK | R177: =IF(OR(C177="",H177=""),"Missing Key","OK") -> OK | S177: =IF(L177>=1000,"Large",IF(L177>=500,"Medium","Small")) -> Small
A178: ORD000980 | B178: 46074 | C178: DSP0072 | D178: =IFERROR(VLOOKUP(C178,customer_lookup!$A:$E,2,FALSE),"") -> OK Account 0072 | E178: =IFERROR(VLOOKUP(C178,customer_lookup!$A:$E,3,FALSE),"") -> OK | F178: =IFERROR(VLOOKUP(C178,customer_lookup!$A:$E,5,FALSE),"") -> Avery | G178: Wholesale | H178: SKU0013 | I178: =IFERROR(VLOOKUP(H178,product_lookup!$A:$D,2,FALSE),"") -> Sour Cherry THC Gummies | J178: 24 | K178: 10.07 | L178: =J178*K178 -> 241.68 | M178: Approved | N178: 46075 | O178: =SUMIF(inventory_snapshot!$B:$B,H178,inventory_snapshot!$E:$E) -> 1313 | P178: =IF(O178<J178,"Short","OK") -> OK | Q178: =IF(COUNTIF($A:$A,A178)>1,"Duplicate","OK") -> OK | R178: =IF(OR(C178="",H178=""),"Missing Key","OK") -> OK | S178: =IF(L178>=1000,"Large",IF(L178>=500,"Medium","Small")) -> Small
A179: ORD000012 | B179: 46100 | C179: DSP0048 | D179: =IFERROR(VLOOKUP(C179,customer_lookup!$A:$E,2,FALSE),"") -> OK Account 0048 | E179: =IFERROR(VLOOKUP(C179,customer_lookup!$A:$E,3,FALSE),"") -> OK | F179: =IFERROR(VLOOKUP(C179,customer_lookup!$A:$E,5,FALSE),"") -> Casey | G179: Retail | H179: SKU0006 | I179: =IFERROR(VLOOKUP(H179,product_lookup!$A:$D,2,FALSE),"") -> Kiwi 1:1 Gummies | J179: 96 | K179: 11.75 | L179: =J179*K179 -> 1128 | M179: Fulfilled | N179: 46103 | O179: =SUMIF(inventory_snapshot!$B:$B,H179,inventory_snapshot!$E:$E) -> 1136 | P179: =IF(O179<J179,"Short","OK") -> OK | Q179: =IF(COUNTIF($A:$A,A179)>1,"Duplicate","OK") -> OK | R179: =IF(OR(C179="",H179=""),"Missing Key","OK") -> OK | S179: =IF(L179>=1000,"Large",IF(L179>=500,"Medium","Small")) -> Large
A180: ORD000021 | B180: 46074 | C180: DSP0038 | D180: =IFERROR(VLOOKUP(C180,customer_lookup!$A:$E,2,FALSE),"") -> WA Account 0038 | E180: =IFERROR(VLOOKUP(C180,customer_lookup!$A:$E,3,FALSE),"") -> WA | F180: =IFERROR(VLOOKUP(C180,customer_lookup!$A:$E,5,FALSE),"") -> Casey | G180: Wholesale | H180: SKU0008 | I180: =IFERROR(VLOOKUP(H180,product_lookup!$A:$D,2,FALSE),"") -> Peach 2:1 Gummies | J180: 24 | K180: 10.33 | L180: =J180*K180 -> 247.92 | M180: Fulfilled | N180: 46083 | O180: =SUMIF(inventory_snapshot!$B:$B,H180,inventory_snapshot!$E:$E) -> 1732 | P180: =IF(O180<J180,"Short","OK") -> OK | Q180: =IF(COUNTIF($A:$A,A180)>1,"Duplicate","OK") -> OK | R180: =IF(OR(C180="",H180=""),"Missing Key","OK") -> OK | S180: =IF(L180>=1000,"Large",IF(L180>=500,"Medium","Small")) -> Small
A181: ORD000033 | B181: 46140 | C181: DSP0077 | D181: =IFERROR(VLOOKUP(C181,customer_lookup!$A:$E,2,FALSE),"") -> AZ Account 0077 | E181: =IFERROR(VLOOKUP(C181,customer_lookup!$A:$E,3,FALSE),"") -> AZ | F181: =IFERROR(VLOOKUP(C181,customer_lookup!$A:$E,5,FALSE),"") -> Casey | G181: Wholesale | H181: SKU0019 | I181: =IFERROR(VLOOKUP(H181,product_lookup!$A:$D,2,FALSE),"") -> Cranberry Sparkling Beverage | J181: 30 | K181: 7.66 | L181: =J181*K181 -> 229.8 | M181: Rejected | N181: 46147 | O181: =SUMIF(inventory_snapshot!$B:$B,H181,inventory_snapshot!$E:$E) -> 1152 | P181: =IF(O181<J181,"Short","OK") -> OK | Q181: =IF(COUNTIF($A:$A,A181)>1,"Duplicate","OK") -> OK | R181: =IF(OR(C181="",H181=""),"Missing Key","OK") -> OK | S181: =IF(L181>=1000,"Large",IF(L181>=500,"Medium","Small")) -> Small
A182: ORD000037 | B182: 46064 | C182: DSP0053 | D182: =IFERROR(VLOOKUP(C182,customer_lookup!$A:$E,2,FALSE),"") -> AZ Account 0053 | E182: =IFERROR(VLOOKUP(C182,customer_lookup!$A:$E,3,FALSE),"") -> AZ | F182: =IFERROR(VLOOKUP(C182,customer_lookup!$A:$E,5,FALSE),"") -> Casey | G182: Wholesale | H182: SKU0011 | I182: =IFERROR(VLOOKUP(H182,product_lookup!$A:$D,2,FALSE),"") -> Raspberry THC Gummies | J182: 120 | K182: 9.67 | L182: =J182*K182 -> 1160.4 | M182: Approved | N182: 46072 | O182: =SUMIF(inventory_snapshot!$B:$B,H182,inventory_snapshot!$E:$E) -> 1417 | P182: =IF(O182<J182,"Short","OK") -> OK | Q182: =IF(COUNTIF($A:$A,A182)>1,"Duplicate","OK") -> OK | R182: =IF(OR(C182="",H182=""),"Missing Key","OK") -> OK | S182: =IF(L182>=1000,"Large",IF(L182>=500,"Medium","Small")) -> Large
A183: ORD000040 | B183: 46093 | C183: DSP0027 | D183: =IFERROR(VLOOKUP(C183,customer_lookup!$A:$E,2,FALSE),"") -> CA Account 0027 | E183: =IFERROR(VLOOKUP(C183,customer_lookup!$A:$E,3,FALSE),"") -> CA | F183: =IFERROR(VLOOKUP(C183,customer_lookup!$A:$E,5,FALSE),"") -> Casey | G183: Retail | H183: SKU0009 | I183: =IFERROR(VLOOKUP(H183,product_lookup!$A:$D,2,FALSE),"") -> Pear 1:1 Gummies | J183: 18 | K183: 12.21 | L183: =J183*K183 -> 219.78 | M183: Pending | N183: 46095 | O183: =SUMIF(inventory_snapshot!$B:$B,H183,inventory_snapshot!$E:$E) -> 981 | P183: =IF(O183<J183,"Short","OK") -> OK | Q183: =IF(COUNTIF($A:$A,A183)>1,"Duplicate","OK") -> OK | R183: =IF(OR(C183="",H183=""),"Missing Key","OK") -> OK | S183: =IF(L183>=1000,"Large",IF(L183>=500,"Medium","Small")) -> Small
A184: ORD000049 | B184: 46106 | C184: DSP0080 | D184: =IFERROR(VLOOKUP(C184,customer_lookup!$A:$E,2,FALSE),"") -> MI Account 0080 | E184: =IFERROR(VLOOKUP(C184,customer_lookup!$A:$E,3,FALSE),"") -> MI | F184: =IFERROR(VLOOKUP(C184,customer_lookup!$A:$E,5,FALSE),"") -> Casey | G184: Distributor | H184: SKU0013 | I184: =IFERROR(VLOOKUP(H184,product_lookup!$A:$D,2,FALSE),"") -> Sour Cherry THC Gummies | J184: 12 | K184: 11.51 | L184: =J184*K184 -> 138.12 | M184: Fulfilled | N184: 46113 | O184: =SUMIF(inventory_snapshot!$B:$B,H184,inventory_snapshot!$E:$E) -> 1313 | P184: =IF(O184<J184,"Short","OK") -> OK | Q184: =IF(COUNTIF($A:$A,A184)>1,"Duplicate","OK") -> OK | R184: =IF(OR(C184="",H184=""),"Missing Key","OK") -> OK | S184: =IF(L184>=1000,"Large",IF(L184>=500,"Medium","Small")) -> Small
A185: ORD000051 | B185: 46120 | C185: DSP0056 | D185: =IFERROR(VLOOKUP(C185,customer_lookup!$A:$E,2,FALSE),"") -> MI Account 0056 | E185: =IFERROR(VLOOKUP(C185,customer_lookup!$A:$E,3,FALSE),"") -> MI | F185: =IFERROR(VLOOKUP(C185,customer_lookup!$A:$E,5,FALSE),"") -> Casey | G185: Wholesale | H185: SKU0004 | I185: =IFERROR(VLOOKUP(H185,product_lookup!$A:$D,2,FALSE),"") -> Grapefruit 1:1:1 Gummies | J185: 120 | K185: 11.19 | L185: =J185*K185 -> 1342.8 | M185: Submitted | N185: 46125 | O185: =SUMIF(inventory_snapshot!$B:$B,H185,inventory_snapshot!$E:$E) -> 1751 | P185: =IF(O185<J185,"Short","OK") -> OK | Q185: =IF(COUNTIF($A:$A,A185)>1,"Duplicate","OK") -> OK | R185: =IF(OR(C185="",H185=""),"Missing Key","OK") -> OK | S185: =IF(L185>=1000,"Large",IF(L185>=500,"Medium","Small")) -> Large
... A367: ORD000489 | B367: 46082 | C367: DSP0107 | D367: =IFERROR(VLOOKUP(C367,customer_lookup!$A:$E,2,FALSE),"") -> NY Account 0107 | E367: =IFERROR(VLOOKUP(C367,customer_lookup!$A:$E,3,FALSE),"") -> NY | F367: =IFERROR(VLOOKUP(C367,customer_lookup!$A:$E,5,FALSE),"") -> Drew | G367: Distributor | H367: SKU0003 | I367: =IFERROR(VLOOKUP(H367,product_lookup!$A:$D,2,FALSE),"") -> Elderberry 2:1 Gummies | J367: 120 | K367: 10.03 | L367: =J367*K367 -> 1203.6 | M367: Fulfilled | N367: 46089 | O367: =SUMIF(inventory_snapshot!$B:$B,H367,inventory_snapshot!$E:$E) -> 1633 | P367: =IF(O367<J367,"Short","OK") -> OK | Q367: =IF(COUNTIF($A:$A,A367)>1,"Duplicate","OK") -> OK | R367: =IF(OR(C367="",H367=""),"Missing Key","OK") -> OK | S367: =IF(L367>=1000,"Large",IF(L367>=500,"Medium","Small")) -> Large
A368: ORD000495 | B368: 46121 | C368: DSP0028 | D368: =IFERROR(VLOOKUP(C368,customer_lookup!$A:$E,2,FALSE),"") -> CO Account 0028 | E368: =IFERROR(VLOOKUP(C368,customer_lookup!$A:$E,3,FALSE),"") -> CO | F368: =IFERROR(VLOOKUP(C368,customer_lookup!$A:$E,5,FALSE),"") -> Drew | G368: Distributor | I368: =IFERROR(VLOOKUP(H368,product_lookup!$A:$D,2,FALSE),"") | J368: 72 | K368: 11.67 | L368: =J368*K368 -> 840.24 | M368: Approved | N368: 46129 | O368: =SUMIF(inventory_snapshot!$B:$B,H368,inventory_snapshot!$E:$E) -> 0 | P368: =IF(O368<J368,"Short","OK") -> Short | Q368: =IF(COUNTIF($A:$A,A368)>1,"Duplicate","OK") -> OK | R368: =IF(OR(C368="",H368=""),"Missing Key","OK") -> Missing Key | S368: =IF(L368>=1000,"Large",IF(L368>=500,"Medium","Small")) -> Medium
A369: ORD000499 | B369: 46116 | C369: DSP0118 | D369: =IFERROR(VLOOKUP(C369,customer_lookup!$A:$E,2,FALSE),"") -> NM Account 0118 | E369: =IFERROR(VLOOKUP(C369,customer_lookup!$A:$E,3,FALSE),"") -> NM | F369: =IFERROR(VLOOKUP(C369,customer_lookup!$A:$E,5,FALSE),"") -> Drew | G369: Wholesale | H369: SKU0007 | I369: =IFERROR(VLOOKUP(H369,product_lookup!$A:$D,2,FALSE),"") -> Marionberry THC Gummies | J369: 12 | K369: 10.71 | L369: =J369*K369 -> 128.52 | M369: Fulfilled | N369: 46126 | O369: =SUMIF(inventory_snapshot!$B:$B,H369,inventory_snapshot!$E:$E) -> 1599 | P369: =IF(O369<J369,"Short","OK") -> OK | Q369: =IF(COUNTIF($A:$A,A369)>1,"Duplicate","OK") -> OK | R369: =IF(OR(C369="",H369=""),"Missing Key","OK") -> OK | S369: =IF(L369>=1000,"Large",IF(L369>=500,"Medium","Small")) -> Small
A370: ORD000515 | B370: 46141 | C370: DSP0006 | D370: =IFERROR(VLOOKUP(C370,customer_lookup!$A:$E,2,FALSE),"") -> NV Account 0006 | E370: =IFERROR(VLOOKUP(C370,customer_lookup!$A:$E,3,FALSE),"") -> NV | F370: =IFERROR(VLOOKUP(C370,customer_lookup!$A:$E,5,FALSE),"") -> Drew | G370: Retail | H370: SKU0008 | I370: =IFERROR(VLOOKUP(H370,product_lookup!$A:$D,2,FALSE),"") -> Peach 2:1 Gummies | J370: 72 | K370: 10.33 | L370: =J370*K370 -> 743.76 | M370: Fulfilled | N370: 46142 | O370: =SUMIF(inventory_snapshot!$B:$B,H370,inventory_snapshot!$E:$E) -> 1732 | P370: =IF(O370<J370,"Short","OK") -> OK | Q370: =IF(COUNTIF($A:$A,A370)>1,"Duplicate","OK") -> OK | R370: =IF(OR(C370="",H370=""),"Missing Key","OK") -> OK | S370: =IF(L370>=1000,"Large",IF(L370>=500,"Medium","Small")) -> Medium
A371: ORD000529 | B371: 46089 | C371: DSP0006 | D371: =IFERROR(VLOOKUP(C371,customer_lookup!$A:$E,2,FALSE),"") -> NV Account 0006 | E371: =IFERROR(VLOOKUP(C371,customer_lookup!$A:$E,3,FALSE),"") -> NV | F371: =IFERROR(VLOOKUP(C371,customer_lookup!$A:$E,5,FALSE),"") -> Drew | G371: Wholesale | H371: SKU0008 | I371: =IFERROR(VLOOKUP(H371,product_lookup!$A:$D,2,FALSE),"") -> Peach 2:1 Gummies | J371: 72 | K371: 10.53 | L371: =J371*K371 -> 758.16 | M371: Fulfilled | N371: 46098 | O371: =SUMIF(inventory_snapshot!$B:$B,H371,inventory_snapshot!$E:$E) -> 1732 | P371: =IF(O371<J371,"Short","OK") -> OK | Q371: =IF(COUNTIF($A:$A,A371)>1,"Duplicate","OK") -> OK | R371: =IF(OR(C371="",H371=""),"Missing Key","OK") -> OK | S371: =IF(L371>=1000,"Large",IF(L371>=500,"Medium","Small")) -> Medium
A372: ORD000538 | B372: 46107 | C372: DSP0028 | D372: =IFERROR(VLOOKUP(C372,customer_lookup!$A:$E,2,FALSE),"") -> CO Account 0028 | E372: =IFERROR(VLOOKUP(C372,customer_lookup!$A:$E,3,FALSE),"") -> CO | F372: =IFERROR(VLOOKUP(C372,customer_lookup!$A:$E,5,FALSE),"") -> Drew | G372: Wholesale | H372: SKU0019 | I372: =IFERROR(VLOOKUP(H372,product_lookup!$A:$D,2,FALSE),"") -> Cranberry Sparkling Beverage | J372: 60 | K372: 7.68 | L372: =J372*K372 -> 460.8 | M372: Pending | N372: 46108 | O372: =SUMIF(inventory_snapshot!$B:$B,H372,inventory_snapshot!$E:$E) -> 1152 | P372: =IF(O372<J372,"Short","OK") -> OK | Q372: =IF(COUNTIF($A:$A,A372)>1,"Duplicate","OK") -> OK | R372: =IF(OR(C372="",H372=""),"Missing Key","OK") -> OK | S372: =IF(L372>=1000,"Large",IF(L372>=500,"Medium","Small")) -> Small
A373: ORD000573 | B373: 46060 | C373: DSP0058 | D373: =IFERROR(VLOOKUP(C373,customer_lookup!$A:$E,2,FALSE),"") -> NM Account 0058 | E373: =IFERROR(VLOOKUP(C373,customer_lookup!$A:$E,3,FALSE),"") -> NM | F373: =IFERROR(VLOOKUP(C373,customer_lookup!$A:$E,5,FALSE),"") -> Drew | G373: Wholesale | H373: SKU0018 | I373: =IFERROR(VLOOKUP(H373,product_lookup!$A:$D,2,FALSE),"") -> Lemon Sparkling Beverage | J373: 48 | K373: 7.42 | L373: =J373*K373 -> 356.16 | M373: Pending | N373: 46066 | O373: =SUMIF(inventory_snapshot!$B:$B,H373,inventory_snapshot!$E:$E) -> 1360 | P373: =IF(O373<J373,"Short","OK") -> OK | Q373: =IF(COUNTIF($A:$A,A373)>1,"Duplicate","OK") -> OK | R373: =IF(OR(C373="",H373=""),"Missing Key","OK") -> OK | S373: =IF(L373>=1000,"Large",IF(L373>=500,"Medium","Small")) -> Small
A374: ORD000657 | B374: 46034 | C374: DSP0058 | D374: =IFERROR(VLOOKUP(C374,customer_lookup!$A:$E,2,FALSE),"") -> NM Account 0058 | E374: =IFERROR(VLOOKUP(C374,customer_lookup!$A:$E,3,FALSE),"") -> NM | F374: =IFERROR(VLOOKUP(C374,customer_lookup!$A:$E,5,FALSE),"") -> Drew | G374: Distributor | H374: SKU0018 | I374: =IFERROR(VLOOKUP(H374,product_lookup!$A:$D,2,FALSE),"") -> Lemon Sparkling Beverage | J374: 24 | K374: 7.58 | L374: =J374*K374 -> 181.92 | M374: Pending | N374: 46042 | O374: =SUMIF(inventory_snapshot!$B:$B,H374,inventory_snapshot!$E:$E) -> 1360 | P374: =IF(O374<J374,"Short","OK") -> OK | Q374: =IF(COUNTIF($A:$A,A374)>1,"Duplicate","OK") -> OK | R374: =IF(OR(C374="",H374=""),"Missing Key","OK") -> OK | S374: =IF(L374>=1000,"Large",IF(L374>=500,"Medium","Small")) -> Small
A375: ORD000661 | B375: 46061 | C375: DSP0107 | D375: =IFERROR(VLOOKUP(C375,customer_lookup!$A:$E,2,FALSE),"") -> NY Account 0107 | E375: =IFERROR(VLOOKUP(C375,customer_lookup!$A:$E,3,FALSE),"") -> NY | F375: =IFERROR(VLOOKUP(C375,customer_lookup!$A:$E,5,FALSE),"") -> Drew | G375: Wholesale | H375: SKU0019 | I375: =IFERROR(VLOOKUP(H375,product_lookup!$A:$D,2,FALSE),"") -> Cranberry Sparkling Beverage | J375: 60 | K375: 7.84 | L375: =J375*K375 -> 470.4 | M375: Rejected | N375: 46062 | O375: =SUMIF(inventory_snapshot!$B:$B,H375,inventory_snapshot!$E:$E) -> 1152 | P375: =IF(O375<J375,"Short","OK") -> OK | Q375: =IF(COUNTIF($A:$A,A375)>1,"Duplicate","OK") -> OK | R375: =IF(OR(C375="",H375=""),"Missing Key","OK") -> OK | S375: =IF(L375>=1000,"Large",IF(L375>=500,"Medium","Small")) -> Small
A376: ORD000673 | B376: 46124 | C376: DSP0014 | D376: =IFERROR(VLOOKUP(C376,customer_lookup!$A:$E,2,FALSE),"") -> WA Account 0014 | E376: =IFERROR(VLOOKUP(C376,customer_lookup!$A:$E,3,FALSE),"") -> WA | F376: =IFERROR(VLOOKUP(C376,customer_lookup!$A:$E,5,FALSE),"") -> Drew | G376: Wholesale | H376: SKU0002 | I376: =IFERROR(VLOOKUP(H376,product_lookup!$A:$D,2,FALSE),"") -> Boysenberry 1:1:1 Gummies | J376: 120 | K376: 10.53 | L376: =J376*K376 -> 1263.6 | M376: Submitted | N376: 46129 | O376: =SUMIF(inventory_snapshot!$B:$B,H376,inventory_snapshot!$E:$E) -> 2007 | P376: =IF(O376<J376,"Short","OK") -> OK | Q376: =IF(COUNTIF($A:$A,A376)>1,"Duplicate","OK") -> OK | R376: =IF(OR(C376="",H376=""),"Missing Key","OK") -> OK | S376: =IF(L376>=1000,"Large",IF(L376>=500,"Medium","Small")) -> Large
A377: ORD000678 | B377: 46129 | C377: DSP0014 | D377: =IFERROR(VLOOKUP(C377,customer_lookup!$A:$E,2,FALSE),"") -> WA Account 0014 | E377: =IFERROR(VLOOKUP(C377,customer_lookup!$A:$E,3,FALSE),"") -> WA | F377: =IFERROR(VLOOKUP(C377,customer_lookup!$A:$E,5,FALSE),"") -> Drew | G377: Wholesale | H377: SKU0006 | I377: =IFERROR(VLOOKUP(H377,product_lookup!$A:$D,2,FALSE),"") -> Kiwi 1:1 Gummies | J377: 36 | K377: 11.78 | L377: =J377*K377 -> 424.08 | M377: Pending | N377: 46136 | O377: =SUMIF(inventory_snapshot!$B:$B,H377,inventory_snapshot!$E:$E) -> 1136 | P377: =IF(O377<J377,"Short","OK") -> OK | Q377: =IF(COUNTIF($A:$A,A377)>1,"Duplicate","OK") -> OK | R377: =IF(OR(C377="",H377=""),"Missing Key","OK") -> OK | S377: =IF(L377>=1000,"Large",IF(L377>=500,"Medium","Small")) -> Small
...

Sheet erp_invoices
A1: invoice_id | B1: order_id | C1: invoice_date | D1: customer_id | E1: sku | F1: qty_invoiced | G1: invoice_amount | H1: invoice_status | I1: qty_variance_vs_order | J1: amount_variance_vs_order | K1: orphan_invoice_flag
A2: INV000001 | B2: ORD000001 | C2: 46065 | D2: DSP0072 | E2: SKU0020 | F2: 66 | G2: 522.72 | H2: Review | I2: =F2-IFERROR(VLOOKUP(B2,crm_orders!$A:$S,10,FALSE),0) -> 6 | J2: =G2-IFERROR(VLOOKUP(B2,crm_orders!$A:$S,12,FALSE),0) -> 47.52 | K2: =IF(COUNTIF(crm_orders!$A:$A,B2)=0,"Orphan","OK") -> OK
A3: INV000002 | B3: ORD000002 | C3: 46083 | D3: DSP0111 | E3: SKU0016 | F3: 30 | G3: 236.4 | H3: Posted | I3: =F3-IFERROR(VLOOKUP(B3,crm_orders!$A:$S,10,FALSE),0) -> 0 | J3: =G3-IFERROR(VLOOKUP(B3,crm_orders!$A:$S,12,FALSE),0) -> 0 | K3: =IF(COUNTIF(crm_orders!$A:$A,B3)=0,"Orphan","OK") -> OK
A4: INV000003 | B4: ORD000003 | C4: 46128 | D4: DSP0057 | E4: SKU0003 | F4: 30 | G4: 312.6 | H4: Posted | I4: =F4-IFERROR(VLOOKUP(B4,crm_orders!$A:$S,10,FALSE),0) -> 0 | J4: =G4-IFERROR(VLOOKUP(B4,crm_orders!$A:$S,12,FALSE),0) -> 0 | K4: =IF(COUNTIF(crm_orders!$A:$A,B4)=0,"Orphan","OK") -> OK
A5: INV000004 | B5: ORD000004 | C5: 46122 | D5: DSP0089 | E5: SKU0005 | F5: 24 | G5: 224.64 | H5: Posted | I5: =F5-IFERROR(VLOOKUP(B5,crm_orders!$A:$S,10,FALSE),0) -> 0 | J5: =G5-IFERROR(VLOOKUP(B5,crm_orders!$A:$S,12,FALSE),0) -> 0 | K5: =IF(COUNTIF(crm_orders!$A:$A,B5)=0,"Orphan","OK") -> OK
A6: INV000005 | B6: ORD000005 | C6: 46113 | D6: DSP0050 | E6: SKU0019 | F6: 6 | G6: 49.8 | H6: Posted | I6: =F6-IFERROR(VLOOKUP(B6,crm_orders!$A:$S,10,FALSE),0) -> 0 | J6: =G6-IFERROR(VLOOKUP(B6,crm_orders!$A:$S,12,FALSE),0) -> 0 | K6: =IF(COUNTIF(crm_orders!$A:$A,B6)=0,"Orphan","OK") -> OK
A7: INV000006 | B7: ORD000006 | C7: 46103 | D7: DSP0050 | E7: SKU0014 | F7: 48 | G7: 546.72 | H7: Partial | I7: =F7-IFERROR(VLOOKUP(B7,crm_orders!$A:$S,10,FALSE),0) -> -24 | J7: =G7-IFERROR(VLOOKUP(B7,crm_orders!$A:$S,12,FALSE),0) -> -273.36 | K7: =IF(COUNTIF(crm_orders!$A:$A,B7)=0,"Orphan","OK") -> OK
A8: INV000007 | B8: ORD000007 | C8: 46117 | D8: DSP0044 | E8: SKU0013 | F8: 18 | G8: 206.64 | H8: Posted | I8: =F8-IFERROR(VLOOKUP(B8,crm_orders!$A:$S,10,FALSE),0) -> 0 | J8: =G8-IFERROR(VLOOKUP(B8,crm_orders!$A:$S,12,FALSE),0) -> 0 | K8: =IF(COUNTIF(crm_orders!$A:$A,B8)=0,"Orphan","OK") -> OK
A9: INV000008 | B9: ORD000008 | C9: 46036 | D9: DSP0073 | E9: SKU0001 | F9: 132 | G9: 1301.52 | H9: Review | I9: =F9-IFERROR(VLOOKUP(B9,crm_orders!$A:$S,10,FALSE),0) -> 12 | J9: =G9-IFERROR(VLOOKUP(B9,crm_orders!$A:$S,12,FALSE),0) -> 118.32 | K9: =IF(COUNTIF(crm_orders!$A:$A,B9)=0,"Orphan","OK") -> OK
A10: INV000009 | B10: ORD000009 | C10: 46132 | D10: DSP0042 | E10: SKU0011 | F10: 48 | G10: 481.44 | H10: Posted | I10: =F10-IFERROR(VLOOKUP(B10,crm_orders!$A:$S,10,FALSE),0) -> 0 | J10: =G10-IFERROR(VLOOKUP(B10,crm_orders!$A:$S,12,FALSE),0) -> 0 | K10: =IF(COUNTIF(crm_orders!$A:$A,B10)=0,"Orphan","OK") -> OK
A11: INV000010 | B11: ORD000010 | C11: 46063 | D11: DSP0007 | E11: SKU0012 | F11: 120 | G11: 1150.8 | H11: Posted | I11: =F11-IFERROR(VLOOKUP(B11,crm_orders!$A:$S,10,FALSE),0) -> 0 | J11: =G11-IFERROR(VLOOKUP(B11,crm_orders!$A:$S,12,FALSE),0) -> 0 | K11: =IF(COUNTIF(crm_orders!$A:$A,B11)=0,"Orphan","OK") -> OK
A12: INV000011 | B12: ORD000011 | C12: 46045 | D12: DSP0003 | E12: SKU0020 | F12: 18 | G12: 129.06 | H12: Partial | I12: =F12-IFERROR(VLOOKUP(B12,crm_orders!$A:$S,10,FALSE),0) -> -6 | J12: =G12-IFERROR(VLOOKUP(B12,crm_orders!$A:$S,12,FALSE),0) -> -43.02 | K12: =IF(COUNTIF(crm_orders!$A:$A,B12)=0,"Orphan","OK") -> OK
A13: INV000012 | B13: ORD000012 | C13: 46107 | D13: DSP0048 | E13: SKU0006 | F13: 96 | G13: 1128 | H13: Posted | I13: =F13-IFERROR(VLOOKUP(B13,crm_orders!$A:$S,10,FALSE),0) -> 0 | J13: =G13-IFERROR(VLOOKUP(B13,crm_orders!$A:$S,12,FALSE),0) -> 0 | K13: =IF(COUNTIF(crm_orders!$A:$A,B13)=0,"Orphan","OK") -> OK
... A110: INV000109 | B110: ORD000116 | C110: 46047 | D110: DSP0068 | E110: SKU0014 | F110: 30 | G110: 305.7 | H110: Posted | I110: =F110-IFERROR(VLOOKUP(B110,crm_orders!$A:$S,10,FALSE),0) -> 0 | J110: =G110-IFERROR(VLOOKUP(B110,crm_orders!$A:$S,12,FALSE),0) -> 0 | K110: =IF(COUNTIF(crm_orders!$A:$A,B110)=0,"Orphan","OK") -> OK
A111: INV000110 | B111: ORD000117 | C111: 46109 | D111: DSP0116 | F111: 72 | G111: 487.44 | H111: Posted | I111: =F111-IFERROR(VLOOKUP(B111,crm_orders!$A:$S,10,FALSE),0) -> 0 | J111: =G111-IFERROR(VLOOKUP(B111,crm_orders!$A:$S,12,FALSE),0) -> 0 | K111: =IF(COUNTIF(crm_orders!$A:$A,B111)=0,"Orphan","OK") -> OK
A112: INV000111 | B112: ORD000118 | C112: 46109 | D112: DSP0046 | E112: SKU0008 | F112: 48 | G112: 483.84 | H112: Posted | I112: =F112-IFERROR(VLOOKUP(B112,crm_orders!$A:$S,10,FALSE),0) -> 0 | J112: =G112-IFERROR(VLOOKUP(B112,crm_orders!$A:$S,12,FALSE),0) -> 0 | K112: =IF(COUNTIF(crm_orders!$A:$A,B112)=0,"Orphan","OK") -> OK
A113: INV000112 | B113: ORD000119 | C113: 46106 | D113: DSP0065 | E113: SKU0017 | F113: 6 | G113: 44.04 | H113: Posted | I113: =F113-IFERROR(VLOOKUP(B113,crm_orders!$A:$S,10,FALSE),0) -> 0 | J113: =G113-IFERROR(VLOOKUP(B113,crm_orders!$A:$S,12,FALSE),0) -> 0 | K113: =IF(COUNTIF(crm_orders!$A:$A,B113)=0,"Orphan","OK") -> OK
A114: INV000113 | B114: ORD000121 | C114: 46130 | D114: DSP0044 | E114: SKU0006 | F114: 120 | G114: 1280.4 | H114: Posted | I114: =F114-IFERROR(VLOOKUP(B114,crm_orders!$A:$S,10,FALSE),0) -> 0 | J114: =G114-IFERROR(VLOOKUP(B114,crm_orders!$A:$S,12,FALSE),0) -> 0 | K114: =IF(COUNTIF(crm_orders!$A:$A,B114)=0,"Orphan","OK") -> OK
A115: INV000114 | B115: ORD000122 | C115: 46066 | D115: DSP0059 | E115: SKU0002 | F115: 24 | G115: 220.13 | H115: Review | I115: =F115-IFERROR(VLOOKUP(B115,crm_orders!$A:$S,10,FALSE),0) -> 0 | J115: =G115-IFERROR(VLOOKUP(B115,crm_orders!$A:$S,12,FALSE),0) -> -8.83 | K115: =IF(COUNTIF(crm_orders!$A:$A,B115)=0,"Orphan","OK") -> OK
A116: INV000115 | B116: ORD000123 | C116: 46065 | D116: DSP0070 | E116: SKU0016 | F116: 6 | G116: 47.28 | H116: Posted | I116: =F116-IFERROR(VLOOKUP(B116,crm_orders!$A:$S,10,FALSE),0) -> 0 | J116: =G116-IFERROR(VLOOKUP(B116,crm_orders!$A:$S,12,FALSE),0) -> 0 | K116: =IF(COUNTIF(crm_orders!$A:$A,B116)=0,"Orphan","OK") -> OK
A117: INV000116 | B117: ORD000124 | C117: 46085 | D117: DSP0016 | E117: SKU0012 | F117: 42 | G117: 461.31 | H117: Review | I117: =F117-IFERROR(VLOOKUP(B117,crm_orders!$A:$S,10,FALSE),0) -> -6 | J117: =G117-IFERROR(VLOOKUP(B117,crm_orders!$A:$S,12,FALSE),0) -> -67.17 | K117: =IF(COUNTIF(crm_orders!$A:$A,B117)=0,"Orphan","OK") -> OK
A118: INV000117 | B118: ORD000125 | C118: 46064 | D118: DSP0119 | E118: SKU0017 | F118: 12 | G118: 94.08 | H118: Posted | I118: =F118-IFERROR(VLOOKUP(B118,crm_orders!$A:$S,10,FALSE),0) -> 0 | J118: =G118-IFERROR(VLOOKUP(B118,crm_orders!$A:$S,12,FALSE),0) -> 0 | K118: =IF(COUNTIF(crm_orders!$A:$A,B118)=0,"Orphan","OK") -> OK
A119: INV000118 | B119: ORD000126 | C119: 46116 | D119: DSP0011 | E119: SKU0011 | F119: 30 | G119: 297.82 | H119: Review | I119: =F119-IFERROR(VLOOKUP(B119,crm_orders!$A:$S,10,FALSE),0) -> 0 | J119: =G119-IFERROR(VLOOKUP(B119,crm_orders!$A:$S,12,FALSE),0) -> -4.88 | K119: =IF(COUNTIF(crm_orders!$A:$A,B119)=0,"Orphan","OK") -> OK
A120: INV000119 | B120: ORD000127 | C120: 46109 | D120: DSP0112 | E120: SKU0012 | F120: 48 | G120: 481.44 | H120: Posted | I120: =F120-IFERROR(VLOOKUP(B120,crm_orders!$A:$S,10,FALSE),0) -> 0 | J120: =G120-IFERROR(VLOOKUP(B120,crm_orders!$A:$S,12,FALSE),0) -> 0 | K120: =IF(COUNTIF(crm_orders!$A:$A,B120)=0,"Orphan","OK") -> OK
A121: INV000120 | B121: ORD000128 | C121: 46036 | D121: DSP0066 | E121: SKU0006 | F121: 6 | G121: 66.82 | H121: Review | I121: =F121-IFERROR(VLOOKUP(B121,crm_orders!$A:$S,10,FALSE),0) -> -12 | J121: =G121-IFERROR(VLOOKUP(B121,crm_orders!$A:$S,12,FALSE),0) -> -140.18 | K121: =IF(COUNTIF(crm_orders!$A:$A,B121)=0,"Orphan","OK") -> OK
A122: INV000121 | B122: ORD000129 | C122: 46084 | D122: DSP0047 | E122: SKU0012 | F122: 96 | G122: 913.92 | H122: Posted | I122: =F122-IFERROR(VLOOKUP(B122,crm_orders!$A:$S,10,FALSE),0) -> 0 | J122: =G122-IFERROR(VLOOKUP(B122,crm_orders!$A:$S,12,FALSE),0) -> 0 | K122: =IF(COUNTIF(crm_orders!$A:$A,B122)=0,"Orphan","OK") -> OK
A123: INV000122 | B123: ORD000130 | C123: 46103 | D123: DSP0074 | E123: SKU0005 | F123: 36 | G123: 361.44 | H123: Posted | I123: =F123-IFERROR(VLOOKUP(B123,crm_orders!$A:$S,10,FALSE),0) -> 0 | J123: =G123-IFERROR(VLOOKUP(B123,crm_orders!$A:$S,12,FALSE),0) -> 0 | K123: =IF(COUNTIF(crm_orders!$A:$A,B123)=0,"Orphan","OK") -> OK
... A453: INV000452 | B453: ORD000494 | C453: 46139 | D453: DSP0071 | E453: SKU0011 | F453: 36 | G453: 371.52 | H453: Posted | I453: =F453-IFERROR(VLOOKUP(B453,crm_orders!$A:$S,10,FALSE),0) -> 0 | J453: =G453-IFERROR(VLOOKUP(B453,crm_orders!$A:$S,12,FALSE),0) -> 0 | K453: =IF(COUNTIF(crm_orders!$A:$A,B453)=0,"Orphan","OK") -> OK
A454: INV000453 | B454: ORD000495 | C454: 46133 | D454: DSP0028 | F454: 72 | G454: 828.58 | H454: Review | I454: =F454-IFERROR(VLOOKUP(B454,crm_orders!$A:$S,10,FALSE),0) -> 0 | J454: =G454-IFERROR(VLOOKUP(B454,crm_orders!$A:$S,12,FALSE),0) -> -11.66 | K454: =IF(COUNTIF(crm_orders!$A:$A,B454)=0,"Orphan","OK") -> OK
A455: INV000454 | B455: ORD000497 | C455: 46133 | D455: DSP0041 | E455: SKU0001 | F455: 30 | G455: 325.2 | H455: Posted | I455: =F455-IFERROR(VLOOKUP(B455,crm_orders!$A:$S,10,FALSE),0) -> 0 | J455: =G455-IFERROR(VLOOKUP(B455,crm_orders!$A:$S,12,FALSE),0) -> 0 | K455: =IF(COUNTIF(crm_orders!$A:$A,B455)=0,"Orphan","OK") -> OK
A456: INV000455 | B456: ORD000498 | C456: 46042 | D456: DSP0046 | E456: SKU0005 | F456: 30 | G456: 299.4 | H456: Posted | I456: =F456-IFERROR(VLOOKUP(B456,crm_orders!$A:$S,10,FALSE),0) -> 0 | J456: =G456-IFERROR(VLOOKUP(B456,crm_orders!$A:$S,12,FALSE),0) -> 0 | K456: =IF(COUNTIF(crm_orders!$A:$A,B456)=0,"Orphan","OK") -> OK
A457: INV000456 | B457: ORD000499 | C457: 46119 | D457: DSP0118 | E457: SKU0007 | F457: 12 | G457: 128.52 | H457: Posted | I457: =F457-IFERROR(VLOOKUP(B457,crm_orders!$A:$S,10,FALSE),0) -> 0 | J457: =G457-IFERROR(VLOOKUP(B457,crm_orders!$A:$S,12,FALSE),0) -> 0 | K457: =IF(COUNTIF(crm_orders!$A:$A,B457)=0,"Orphan","OK") -> OK
A458: INV000457 | B458: ORD000500 | C458: 46041 | D458: DSP0083 | E458: SKU0010 | F458: 96 | G458: 1031.04 | H458: Posted | I458: =F458-IFERROR(VLOOKUP(B458,crm_orders!$A:$S,10,FALSE),0) -> 0 | J458: =G458-IFERROR(VLOOKUP(B458,crm_orders!$A:$S,12,FALSE),0) -> 0 | K458: =IF(COUNTIF(crm_orders!$A:$A,B458)=0,"Orphan","OK") -> OK
A459: INV000458 | B459: ORD000501 | C459: 46139 | D459: DSP0054 | E459: SKU0004 | F459: 24 | G459: 270.72 | H459: Posted | I459: =F459-IFERROR(VLOOKUP(B459,crm_orders!$A:$S,10,FALSE),0) -> 0 | J459: =G459-IFERROR(VLOOKUP(B459,crm_orders!$A:$S,12,FALSE),0) -> 0 | K459: =IF(COUNTIF(crm_orders!$A:$A,B459)=0,"Orphan","OK") -> OK
A460: INV000459 | B460: ORD000502 | C460: 46096 | D460: DSP0041 | E460: SKU0018 | F460: 18 | G460: 126 | H460: Posted | I460: =F460-IFERROR(VLOOKUP(B460,crm_orders!$A:$S,10,FALSE),0) -> 0 | J460: =G460-IFERROR(VLOOKUP(B460,crm_orders!$A:$S,12,FALSE),0) -> 0 | K460: =IF(COUNTIF(crm_orders!$A:$A,B460)=0,"Orphan","OK") -> OK
A461: INV000460 | B461: ORD000503 | C461: 46046 | D461: DSP0074 | E461: SKU0017 | F461: 24 | G461: 177.6 | H461: Posted | I461: =F461-IFERROR(VLOOKUP(B461,crm_orders!$A:$S,10,FALSE),0) -> 0 | J461: =G461-IFERROR(VLOOKUP(B461,crm_orders!$A:$S,12,FALSE),0) -> 0 | K461: =IF(COUNTIF(crm_orders!$A:$A,B461)=0,"Orphan","OK") -> OK
A462: INV000461 | B462: ORD000505 | C462: 46076 | D462: DSP0026 | E462: SKU0016 | F462: 120 | G462: 913.2 | H462: Posted | I462: =F462-IFERROR(VLOOKUP(B462,crm_orders!$A:$S,10,FALSE),0) -> 0 | J462: =G462-IFERROR(VLOOKUP(B462,crm_orders!$A:$S,12,FALSE),0) -> 0 | K462: =IF(COUNTIF(crm_orders!$A:$A,B462)=0,"Orphan","OK") -> OK
A463: INV000462 | B463: ORD000507 | C463: 46109 | D463: DSP0045 | E463: SKU0020 | F463: 6 | G463: 49.02 | H463: Posted | I463: =F463-IFERROR(VLOOKUP(B463,crm_orders!$A:$S,10,FALSE),0) -> 0 | J463: =G463-IFERROR(VLOOKUP(B463,crm_orders!$A:$S,12,FALSE),0) -> 0 | K463: =IF(COUNTIF(crm_orders!$A:$A,B463)=0,"Orphan","OK") -> OK
A464: INV000463 | B464: ORD000508 | C464: 46050 | D464: DSP0119 | E464: SKU0008 | F464: 132 | G464: 1383.36 | H464: Review | I464: =F464-IFERROR(VLOOKUP(B464,crm_orders!$A:$S,10,FALSE),0) -> 12 | J464: =G464-IFERROR(VLOOKUP(B464,crm_orders!$A:$S,12,FALSE),0) -> 125.76 | K464: =IF(COUNTIF(crm_orders!$A:$A,B464)=0,"Orphan","OK") -> OK
A465: INV000464 | B465: ORD000509 | C465: 46146 | D465: DSP0080 | E465: SKU0005 | F465: 30 | G465: 277.5 | H465: Posted | I465: =F465-IFERROR(VLOOKUP(B465,crm_orders!$A:$S,10,FALSE),0) -> 0 | J465: =G465-IFERROR(VLOOKUP(B465,crm_orders!$A:$S,12,FALSE),0) -> 0 | K465: =IF(COUNTIF(crm_orders!$A:$A,B465)=0,"Orphan","OK") -> OK
...

Sheet reconciliation_summary
A1: Sales Ops Reconciliation Summary
A2: Compare CRM orders, ERP invoices, inventory flags, returns, and exception counts.
A3: Metric | B3: Formula / Value | C3: Status / Notes
A4: CRM Gross Sales | B4: =SUM(crm_orders!L:L) -> 472328.52 | C4: Total submitted CRM order value
A5: ERP Invoice Amount | B5: =SUM(erp_invoices!G:G) -> 429804.52 | C5: Total posted / reviewed invoice value
A6: Gross Sales Variance | B6: =B5-B4 -> -42524 | C6: ERP minus CRM
A7: Variance % of CRM | B7: =(B6/B4) -> -0.090030558 | C7: Should be investigated when material
A8: CRM Order Count | B8: =COUNTA(crm_orders!A:A)-1 -> 1000 | C8: Expected: 1,000 rows
A9: ERP Invoice Count | B9: =COUNTA(erp_invoices!A:A)-1 -> 934 | C9: Some orders intentionally not invoiced
A10: Open Exceptions | B10: =COUNTIF(exception_log!F:F,"Open") -> 116 | C10: Operational backlog
A11: Critical Exceptions | B11: =COUNTIF(exception_log!D:D,"Critical") -> 24 | C11: Highest priority
A12: Inventory Short Orders | B12: =COUNTIF(crm_orders!P:P,"Short") -> 3 | C12: Orders where available inventory < qty ordered
A13: Duplicate CRM Orders | B13: =COUNTIF(crm_orders!Q:Q,"Duplicate") -> 16 | C13: Duplicate order IDs
A14: Missing Key Orders | B14: =COUNTIF(crm_orders!R:R,"Missing Key") -> 5 | C14: Missing customer_id or sku
A15: Orphan ERP Invoice Count | B15: =COUNTIF(erp_invoices!K:K,"Orphan") -> 15 | C15: Invoices without matching CRM order
A16: Credit Memo Total | B16: =SUM(returns_credit_memos!E:E) -> -15112.55 | C16: Credits / returns reduce revenue
A18: Expanded Operational Controls
A19: Shipment Rows | B19: =COUNTA(warehouse_shipments!A:A)-1 -> 786 | C19: Shipment layer completeness
A20: OTIF Failures | B20: =COUNTIF(warehouse_shipments!L:L,"No") -> 615 | C20: Orders not on time and in full
A21: Compliance Holds | B21: =COUNTIF(order_compliance_review!J:J,"Yes") -> 238 | C21: Orders blocked by license/manifest/SKU rules
A22: AR Outstanding Balance | B22: =SUM(accounts_receivable!I:I) -> 149386.46 | C22: Uncollected invoice balance
A23: AR 90+ Count | B23: =COUNTIF(accounts_receivable!K:K,"90+") -> 26 | C23: Highest-risk receivables bucket
A24: Support Case Count | B24: =COUNTA(customer_support_cases!A:A)-1 -> 340 | C24: Customer-facing issue volume
A25: SLA Breach Count | B25: =COUNTIF(customer_support_cases!L:L,"Breach") -> 268 | C25: Open/closed cases outside SLA
A26: Crosswalk Review Count | B26: =COUNTIF(customer_crosswalk!G:G,"Review") -> 14 | C26: Customer master data mapping risk
A28: Rates
A29: Invoice Coverage Rate | B29: =B9/B8 -> 0.934
A30: Exception Rate of CRM Order Count | B30: =B10/B8 -> 0.116
A31: Critical Exception Rate | B31: =B11/B10 -> 0.20689655
A32: Credit Memo % of CRM | B32: =B16/B4 -> -0.031995845
A33: AR Outstanding % of Invoice Amount | B33: =B22/B5 -> 0.34756838
A34: OTIF Failure Rate | B34: =B20/B19 -> 0.78244275
A35: SLA Breach Rate | B35: =B25/B24 -> 0.78823529

Sheet sla_metrics
A1: SLA Metrics
A2: Operational speed and backlog health across order lifecycle.
A3: Metric | B3: Formula / Value | C3: Target | D3: Status | E3: Notes
A4: Avg hours to ship | B4: =AVERAGE(warehouse_shipments!N:N) -> 186.16794 | C4: 72 | D4: =IF(B4<=C4,"PASS","REVIEW") -> REVIEW | E4: Order date to ship date
A5: OTIF % | B5: =COUNTIF(warehouse_shipments!L:L,"Yes")/(COUNTA(warehouse_shipments!L:L)-1) -> 0.21755725 | C5: 0.85 | D5: =IF(B5>=C5,"PASS","REVIEW") -> REVIEW | E5: On-time and in-full rate
A6: Avg support hours to resolve | B6: =AVERAGE(customer_support_cases!K:K) -> 679.84118 | C6: 72 | D6: =IF(B6<=C6,"PASS","REVIEW") -> REVIEW | E6: Open cases age against SLA too
A7: Support SLA breach count | B7: =COUNTIF(customer_support_cases!L:L,"Breach") -> 268 | C7: 20 | D7: =IF(B7<=C7,"PASS","REVIEW") -> REVIEW | E7: Number of cases past SLA
A8: Open compliance holds | B8: =COUNTIF(order_compliance_review!J:J,"Yes") -> 238 | C8: 15 | D8: =IF(B8<=C8,"PASS","REVIEW") -> REVIEW | E8: Orders blocked by compliance
A9: Credit hold recommendations | B9: =COUNTIF(accounts_receivable!M:M,"Yes") -> 93 | C9: 25 | D9: =IF(B9<=C9,"PASS","REVIEW") -> REVIEW | E9: AR aging based credit risk

Sheet warehouse_shipments
A1: shipment_id | B1: order_id | C1: ship_date | D1: warehouse | E1: carrier | F1: tracking_number | G1: requested_units | H1: shipped_units | I1: short_ship_units | J1: on_time_flag | K1: in_full_flag | L1: otif_flag | M1: fulfillment_status | N1: hours_to_ship | O1: customer_id | P1: state | Q1: channel | R1: sku
A2: SHP000001 | B2: ORD000003 | C2: 46117 | D2: WHSE_OR | E2: FedEx | F2: TRK103295517 | G2: 30 | H2: 30 | I2: 0 | J2: No | K2: Yes | L2: No | M2: Shipped | N2: =IFERROR((C2-VLOOKUP(B2,crm_orders!$A:$S,2,FALSE))*24,0) -> 72 | O2: =IFERROR(VLOOKUP(B2,crm_orders!$A:$S,3,FALSE),"") -> DSP0057 | P2: =IFERROR(VLOOKUP(B2,crm_orders!$A:$S,5,FALSE),"") -> MO | Q2: =IFERROR(VLOOKUP(B2,crm_orders!$A:$S,7,FALSE),"") -> Distributor | R2: =IFERROR(VLOOKUP(B2,crm_orders!$A:$S,8,FALSE),"") -> SKU0003
A3: SHP000002 | B3: ORD000007 | C3: 46126 | D3: WHSE_CA | E3: USPS | F3: TRK938275454 | G3: 18 | H3: 18 | I3: 0 | J3: No | K3: Yes | L3: No | M3: Shipped | N3: =IFERROR((C3-VLOOKUP(B3,crm_orders!$A:$S,2,FALSE))*24,0) -> 264 | O3: =IFERROR(VLOOKUP(B3,crm_orders!$A:$S,3,FALSE),"") -> DSP0044 | P3: =IFERROR(VLOOKUP(B3,crm_orders!$A:$S,5,FALSE),"") -> MI | Q3: =IFERROR(VLOOKUP(B3,crm_orders!$A:$S,7,FALSE),"") -> Distributor | R3: =IFERROR(VLOOKUP(B3,crm_orders!$A:$S,8,FALSE),"") -> SKU0013
A4: SHP000003 | B4: ORD000008 | C4: 46043 | D4: WHSE_MW | E4: UPS | F4: TRK517409720 | G4: 120 | H4: 120 | I4: 0 | J4: No | K4: Yes | L4: No | M4: Shipped | N4: =IFERROR((C4-VLOOKUP(B4,crm_orders!$A:$S,2,FALSE))*24,0) -> 240 | O4: =IFERROR(VLOOKUP(B4,crm_orders!$A:$S,3,FALSE),"") -> DSP0073 | P4: =IFERROR(VLOOKUP(B4,crm_orders!$A:$S,5,FALSE),"") -> OR | Q4: =IFERROR(VLOOKUP(B4,crm_orders!$A:$S,7,FALSE),"") -> Wholesale | R4: =IFERROR(VLOOKUP(B4,crm_orders!$A:$S,8,FALSE),"") -> SKU0001
A5: SHP000004 | B5: ORD000009 | C5: 46123 | D5: WHSE_CA | E5: UPS | F5: TRK381941642 | G5: 48 | H5: 48 | I5: 0 | J5: No | K5: Yes | L5: No | M5: Shipped | N5: =IFERROR((C5-VLOOKUP(B5,crm_orders!$A:$S,2,FALSE))*24,0) -> 72 | O5: =IFERROR(VLOOKUP(B5,crm_orders!$A:$S,3,FALSE),"") -> DSP0042 | P5: =IFERROR(VLOOKUP(B5,crm_orders!$A:$S,5,FALSE),"") -> NV | Q5: =IFERROR(VLOOKUP(B5,crm_orders!$A:$S,7,FALSE),"") -> Wholesale | R5: =IFERROR(VLOOKUP(B5,crm_orders!$A:$S,8,FALSE),"") -> SKU0011
A6: SHP000005 | B6: ORD000010 | C6: 46054 | D6: WHSE_CO | E6: OnTrac | F6: TRK834504404 | G6: 120 | H6: 120 | I6: 0 | J6: No | K6: Yes | L6: No | M6: Shipped | N6: =IFERROR((C6-VLOOKUP(B6,crm_orders!$A:$S,2,FALSE))*24,0) -> 72 | O6: =IFERROR(VLOOKUP(B6,crm_orders!$A:$S,3,FALSE),"") -> DSP0007 | P6: =IFERROR(VLOOKUP(B6,crm_orders!$A:$S,5,FALSE),"") -> IL | Q6: =IFERROR(VLOOKUP(B6,crm_orders!$A:$S,7,FALSE),"") -> Wholesale | R6: =IFERROR(VLOOKUP(B6,crm_orders!$A:$S,8,FALSE),"") -> SKU0012
A7: SHP000006 | B7: ORD000011 | C7: 46047 | D7: WHSE_CO | E7: OnTrac | F7: TRK456854813 | G7: 24 | H7: 24 | I7: 0 | J7: No | K7: Yes | L7: No | M7: Shipped | N7: =IFERROR((C7-VLOOKUP(B7,crm_orders!$A:$S,2,FALSE))*24,0) -> 120 | O7: =IFERROR(VLOOKUP(B7,crm_orders!$A:$S,3,FALSE),"") -> DSP0003 | P7: =IFERROR(VLOOKUP(B7,crm_orders!$A:$S,5,FALSE),"") -> CA | Q7: =IFERROR(VLOOKUP(B7,crm_orders!$A:$S,7,FALSE),"") -> Wholesale | R7: =IFERROR(VLOOKUP(B7,crm_orders!$A:$S,8,FALSE),"") -> SKU0020
A8: SHP000007 | B8: ORD000014 | C8: 46051 | D8: WHSE_CA | E8: OnTrac | F8: TRK592115082 | G8: 30 | H8: 24 | I8: 6 | J8: No | K8: No | L8: No | M8: Short Shipped | N8: =IFERROR((C8-VLOOKUP(B8,crm_orders!$A:$S,2,FALSE))*24,0) -> 360 | O8: =IFERROR(VLOOKUP(B8,crm_orders!$A:$S,3,FALSE),"") -> DSP0081 | P8: =IFERROR(VLOOKUP(B8,crm_orders!$A:$S,5,FALSE),"") -> MO | Q8: =IFERROR(VLOOKUP(B8,crm_orders!$A:$S,7,FALSE),"") -> Wholesale | R8: =IFERROR(VLOOKUP(B8,crm_orders!$A:$S,8,FALSE),"") -> SKU0008
A9: SHP000008 | B9: ORD000016 | C9: 46118 | D9: WHSE_WA | E9: USPS | F9: TRK155479649 | G9: 18 | H9: 18 | I9: 0 | J9: Yes | K9: Yes | L9: Yes | M9: Shipped | N9: =IFERROR((C9-VLOOKUP(B9,crm_orders!$A:$S,2,FALSE))*24,0) -> 120 | O9: =IFERROR(VLOOKUP(B9,crm_orders!$A:$S,3,FALSE),"") -> DSP0082 | P9: =IFERROR(VLOOKUP(B9,crm_orders!$A:$S,5,FALSE),"") -> NM | Q9: =IFERROR(VLOOKUP(B9,crm_orders!$A:$S,7,FALSE),"") -> Distributor | R9: =IFERROR(VLOOKUP(B9,crm_orders!$A:$S,8,FALSE),"") -> SKU0015
A10: SHP000009 | B10: ORD000017 | C10: 46088 | D10: WHSE_WA | E10: FedEx | F10: TRK969495682 | G10: 48 | H10: 48 | I10: 0 | J10: No | K10: Yes | L10: No | M10: Shipped | N10: =IFERROR((C10-VLOOKUP(B10,crm_orders!$A:$S,2,FALSE))*24,0) -> 144 | O10: =IFERROR(VLOOKUP(B10,crm_orders!$A:$S,3,FALSE),"") -> DSP0100 | P10: =IFERROR(VLOOKUP(B10,crm_orders!$A:$S,5,FALSE),"") -> CO | Q10: =IFERROR(VLOOKUP(B10,crm_orders!$A:$S,7,FALSE),"") -> Wholesale | R10: =IFERROR(VLOOKUP(B10,crm_orders!$A:$S,8,FALSE),"") -> SKU0016
A11: SHP000010 | B11: ORD000018 | C11: 46063 | D11: WHSE_CO | E11: UPS | F11: TRK147692456 | G11: 60 | H11: 60 | I11: 0 | J11: No | K11: Yes | L11: No | M11: Shipped | N11: =IFERROR((C11-VLOOKUP(B11,crm_orders!$A:$S,2,FALSE))*24,0) -> 216 | O11: =IFERROR(VLOOKUP(B11,crm_orders!$A:$S,3,FALSE),"") -> DSP0113 | P11: =IFERROR(VLOOKUP(B11,crm_orders!$A:$S,5,FALSE),"") -> AZ | Q11: =IFERROR(VLOOKUP(B11,crm_orders!$A:$S,7,FALSE),"") -> Wholesale | R11: =IFERROR(VLOOKUP(B11,crm_orders!$A:$S,8,FALSE),"") -> SKU0015
A12: SHP000011 | B12: ORD000019 | C12: 46132 | D12: WHSE_OR | E12: OnTrac | F12: TRK702198472 | G12: 30 | H12: 30 | I12: 0 | J12: No | K12: Yes | L12: No | M12: Shipped | N12: =IFERROR((C12-VLOOKUP(B12,crm_orders!$A:$S,2,FALSE))*24,0) -> 168 | O12: =IFERROR(VLOOKUP(B12,crm_orders!$A:$S,3,FALSE),"") -> DSP0028 | P12: =IFERROR(VLOOKUP(B12,crm_orders!$A:$S,5,FALSE),"") -> CO | Q12: =IFERROR(VLOOKUP(B12,crm_orders!$A:$S,7,FALSE),"") -> Retail | R12: =IFERROR(VLOOKUP(B12,crm_orders!$A:$S,8,FALSE),"") -> SKU0012
A13: SHP000012 | B13: ORD000020 | C13: 46063 | D13: WHSE_CO | E13: UPS | F13: TRK806139531 | G13: 48 | H13: 42 | I13: 6 | J13: No | K13: No | L13: No | M13: Short Shipped | N13: =IFERROR((C13-VLOOKUP(B13,crm_orders!$A:$S,2,FALSE))*24,0) -> 240 | O13: =IFERROR(VLOOKUP(B13,crm_orders!$A:$S,3,FALSE),"") -> DSP0025 | P13: =IFERROR(VLOOKUP(B13,crm_orders!$A:$S,5,FALSE),"") -> OR | Q13: =IFERROR(VLOOKUP(B13,crm_orders!$A:$S,7,FALSE),"") -> Retail | R13: =IFERROR(VLOOKUP(B13,crm_orders!$A:$S,8,FALSE),"") -> SKU0003
... A787: SHP000786 | B787: ORD001000 | C787: 46103 | D787: WHSE_CO | E787: Regional Courier | F787: TRK828456114 | G787: 24 | H787: 24 | I787: 0 | J787: No | K787: Yes | L787: No | M787: Shipped | N787: =IFERROR((C787-VLOOKUP(B787,crm_orders!$A:$S,2,FALSE))*24,0) -> 288 | O787: =IFERROR(VLOOKUP(B787,crm_orders!$A:$S,3,FALSE),"") -> DSP0069 | P787: =IFERROR(VLOOKUP(B787,crm_orders!$A:$S,5,FALSE),"") -> MO | Q787: =IFERROR(VLOOKUP(B787,crm_orders!$A:$S,7,FALSE),"") -> Wholesale | R787: =IFERROR(VLOOKUP(B787,crm_orders!$A:$S,8,FALSE),"") -> SKU0016

Sheet accounts_receivable
A1: invoice_id | B1: order_id | C1: customer_id | D1: invoice_date | E1: due_date | F1: invoice_amount | G1: paid_date | H1: payment_amount | I1: outstanding_balance | J1: days_past_due | K1: aging_bucket | L1: collections_status | M1: credit_hold_recommendation
A2: INV000001 | B2: ORD000001 | C2: DSP0072 | D2: 46065 | E2: 46095 | F2: 522.72 | G2: 46135 | H2: 522.72 | I2: =F2-H2 -> 0 | J2: =MAX(0,TODAY()-E2) -> 63 | K2: =IF(I2=0,"Paid",IF(J2<=30,"0-30",IF(J2<=60,"31-60",IF(J2<=90,"61-90","90+")))) -> Paid | L2: =IF(I2=0,"Closed",IF(J2>90,"Escalate",IF(J2>60,"Collections Review",IF(J2>30,"Reminder Sent","Current")))) -> Closed | M2: =IF(OR(K2="61-90",K2="90+"),"Yes","No") -> No
A3: INV000002 | B3: ORD000002 | C3: DSP0111 | D3: 46083 | E3: 46113 | F3: 236.4 | H3: 0 | I3: =F3-H3 -> 236.4 | J3: =MAX(0,TODAY()-E3) -> 45 | K3: =IF(I3=0,"Paid",IF(J3<=30,"0-30",IF(J3<=60,"31-60",IF(J3<=90,"61-90","90+")))) -> 31-60 | L3: =IF(I3=0,"Closed",IF(J3>90,"Escalate",IF(J3>60,"Collections Review",IF(J3>30,"Reminder Sent","Current")))) -> Reminder Sent | M3: =IF(OR(K3="61-90",K3="90+"),"Yes","No") -> No
A4: INV000003 | B4: ORD000003 | C4: DSP0057 | D4: 46128 | E4: 46143 | F4: 312.6 | G4: 46160 | H4: 312.6 | I4: =F4-H4 -> 0 | J4: =MAX(0,TODAY()-E4) -> 15 | K4: =IF(I4=0,"Paid",IF(J4<=30,"0-30",IF(J4<=60,"31-60",IF(J4<=90,"61-90","90+")))) -> Paid | L4: =IF(I4=0,"Closed",IF(J4>90,"Escalate",IF(J4>60,"Collections Review",IF(J4>30,"Reminder Sent","Current")))) -> Closed | M4: =IF(OR(K4="61-90",K4="90+"),"Yes","No") -> No
A5: INV000004 | B5: ORD000004 | C5: DSP0089 | D5: 46122 | E5: 46152 | F5: 224.64 | H5: 0 | I5: =F5-H5 -> 224.64 | J5: =MAX(0,TODAY()-E5) -> 6 | K5: =IF(I5=0,"Paid",IF(J5<=30,"0-30",IF(J5<=60,"31-60",IF(J5<=90,"61-90","90+")))) -> 0-30 | L5: =IF(I5=0,"Closed",IF(J5>90,"Escalate",IF(J5>60,"Collections Review",IF(J5>30,"Reminder Sent","Current")))) -> Current | M5: =IF(OR(K5="61-90",K5="90+"),"Yes","No") -> No
A6: INV000005 | B6: ORD000005 | C6: DSP0050 | D6: 46113 | E6: 46143 | F6: 49.8 | G6: 46155 | H6: 49.8 | I6: =F6-H6 -> 0 | J6: =MAX(0,TODAY()-E6) -> 15 | K6: =IF(I6=0,"Paid",IF(J6<=30,"0-30",IF(J6<=60,"31-60",IF(J6<=90,"61-90","90+")))) -> Paid | L6: =IF(I6=0,"Closed",IF(J6>90,"Escalate",IF(J6>60,"Collections Review",IF(J6>30,"Reminder Sent","Current")))) -> Closed | M6: =IF(OR(K6="61-90",K6="90+"),"Yes","No") -> No
A7: INV000006 | B7: ORD000006 | C7: DSP0050 | D7: 46103 | E7: 46133 | F7: 546.72 | H7: 0 | I7: =F7-H7 -> 546.72 | J7: =MAX(0,TODAY()-E7) -> 25 | K7: =IF(I7=0,"Paid",IF(J7<=30,"0-30",IF(J7<=60,"31-60",IF(J7<=90,"61-90","90+")))) -> 0-30 | L7: =IF(I7=0,"Closed",IF(J7>90,"Escalate",IF(J7>60,"Collections Review",IF(J7>30,"Reminder Sent","Current")))) -> Current | M7: =IF(OR(K7="61-90",K7="90+"),"Yes","No") -> No
A8: INV000007 | B8: ORD000007 | C8: DSP0044 | D8: 46117 | E8: 46132 | F8: 206.64 | G8: 46147 | H8: 206.64 | I8: =F8-H8 -> 0 | J8: =MAX(0,TODAY()-E8) -> 26 | K8: =IF(I8=0,"Paid",IF(J8<=30,"0-30",IF(J8<=60,"31-60",IF(J8<=90,"61-90","90+")))) -> Paid | L8: =IF(I8=0,"Closed",IF(J8>90,"Escalate",IF(J8>60,"Collections Review",IF(J8>30,"Reminder Sent","Current")))) -> Closed | M8: =IF(OR(K8="61-90",K8="90+"),"Yes","No") -> No
